Workbook

Sheet 평가기준
A1: 항목 | B1: 고정값 | C1: 해석·재현 규칙
A2: 평가 데이터 | B2: data/training/front_session_split_v1/test | C2: 누수 방지 후 고정한 test split만 정확도 평가에 사용
A3: 평가 이미지 수 | B3: 437 | C3: 모든 성공 후보에서 반드시 동일
A4: COCO AP confidence 최소값 | B4: 0.001 | C4: 점수 곡선을 보존하기 위한 낮은 수집 threshold
A5: Semantic mIoU threshold | B5: 0.25 | C5: 배포 운용점에서 클래스별 instance mask를 합집합
A6: 지연시간 표본 이미지 | B6: 32 | C6: seed 42로 선택된 동일 이미지 집합
A7: Warm-up / 반복당 측정 | B7: 20 / 200 | C7: GPU 동기화 전후를 포함한 end-to-end in-memory 측정
A8: Benchmark 반복 횟수 | B8: 3 | C8: 반복별 warm-up 후 통계를 재측정
A9: 반복 median CV 경고선 | B9: 0.05 | C9: 초과 시 제외하지 않고 재측정 필요 경고
A10: BBox AP 허용 하락 | B10: 0.01 | C10: B01 TensorRT 재측정값 대비 절대 하락 한계
A11: Mask AP 허용 하락 | B11: 0.01 | C11: B01 TensorRT 재측정값 대비 절대 하락 한계
A12: Semantic mIoU 허용 하락 | B12: 0.02 | C12: B01 TensorRT 재측정값 대비 절대 하락 한계
A13: 실시간 목표 FPS | B13: 30 | C13: 최종 배포 후보 표시 기준
A14: Median latency 예산(ms) | B14: 33.333333 | C14: 30 FPS frame period에 해당
A15: P95 latency 정책 | B15: 보조지표·경고 전용 | C15: 33.33 ms 초과 시 경고하되 배포·Pareto hard gate에는 사용하지 않음
A16: CV 5% 초과 처리 | B16: 지연시간 3회 전체 재측정 최대 1회 | C16: 두 번째 3회를 공식값으로 사용; 여전히 초과하면 최종 권장에서 제외
A17: Pareto 최대화 | B17: Mask AP | C17: 정확도 3종 보존 gate와 측정 유효성 통과 후 적용
A18: Pareto 최소화 | B18: Median latency, engine size | C18: BBox AP, mIoU, P95, GPU memory는 보조지표
A20: 보고 지표 정의
A21: 지표 | B21: 정의
A22: BBox/Mask AP | B22: COCO AP@[IoU=.50:.05:.95], maxDets=100
A23: AP50 / AP75 | B23: 완화/엄격 IoU 조건의 위치·경계 품질
A24: AP small/medium/large | B24: 객체 면적별 성능 편향 점검
A25: AR100 | B25: 이미지당 최대 100개 예측에서 평균 재현율
A26: Semantic mIoU | B26: 클래스별 dataset intersection/union의 macro mean
A27: Median/P95/P99 | B27: 일반·tail latency를 함께 보고
A28: 반복 median 95% CI | B28: 3회 반복 median 평균의 t 구간
A29: GPU memory | B29: 3회 측정 중 max allocated/reserved

Sheet 원시결과
A1: ID | B1: 경량화 계열 | C1: 방식 | D1: 정밀도 | E1: 입력크기 | F1: 1차 판정 | G1: 1차 불통 사유 | H1: 2차 상태 | I1: 2차 실패 사유 | J1: BBox AP | K1: BBox AP50 | L1: BBox AP75 | M1: BBox AP-small | N1: BBox AP-medium | O1: BBox AP-large | P1: BBox AR100 | Q1: Mask AP | R1: Mask AP50 | S1: Mask AP75 | T1: Mask AP-small | U1: Mask AP-medium | V1: Mask AP-large | W1: Mask AR100 | X1: Semantic mIoU | Y1: Mean ms | Z1: Median ms | AA1: P95 ms | AB1: P99 ms | AC1: IQR ms | AD1: 전체 CV | AE1: 반복 Median CV | AF1: 반복 Median CI95 하한 | AG1: 반복 Median CI95 상한 | AH1: FPS | AI1: GPU allocated bytes | AJ1: GPU reserved bytes | AK1: Engine bytes | AL1: 측정 반복 수 | AM1: 총 latency 횟수 | AN1: Engine 경로 | AO1: 평가 JSON | AP1: Benchmark JSON 목록 | AQ1: Test 이미지 수 | AR1: 예측 수 | AS1: Engine SHA256 | AT1: Annotation SHA256 | AU1: 전체 Benchmark JSON 목록 | AV1: CV 재측정 수행 | AW1: CV 재측정 횟수 | AX1: CV 불안정 미해결 | AY1: Latency 측정 라운드
A2: B01 | B2: baseline | C2: none | D2: fp32 | E2: 1x3x504x504 | F2: 통과 | H2: 완료 | J2: 0.73785893 | K2: 0.92687396 | L2: 0.79214494 | M2: 0.31082722 | N2: 0.6103673 | O2: 0.84158753 | P2: 0.87938712 | Q2: 0.6026427 | R2: 0.83992178 | S2: 0.64881188 | T2: 0.056792806 | U2: 0.48866118 | V2: 0.71596522 | W2: 0.72964413 | X2: 0.71200708 | Y2: 46.022159 | Z2: 45.820257 | AA2: 48.561517 | AB2: 49.340607 | AC2: 1.6076312 | AD2: 0.027909928 | AE2: 0.001230759 | AF2: 45.660595 | AG2: 45.940677 | AH2: 21.728663 | AI2: 941561856 | AJ2: 1000341504 | AK2: 135622764 | AL2: 3 | AM2: 600 | AN2: artifacts/experiments/B01/front/model.engine | AO2: results/coco-evaluation/B01-front.json | AP2: ["results/benchmarks/notebook-controlled/20260904_104755/B01/repeat-01/front_tensorrt_fp32_20260904_104843.json", "results/benchmarks/notebook-controlled/20260904_104755/B01/repeat-02/front_tensorrt_fp32_20260904_104901.json", "results/benchmarks/notebook-controlled/20260904_104755/B01/repeat-03/front_tensorrt_fp32_20260904_104919.json"] | AQ2: 437 | AR2: 86415 | AS2: b7800a7c51d9163f3b88030919f15231ff1b262cad9feac52bbd09081684ef6d | AT2: 037949731e462ecb42feb6e61b61fbca555dfe2a3d381464ad36a17b0a7ff9b9 | AU2: ["results/benchmarks/notebook-controlled/20260904_104755/B01/repeat-01/front_tensorrt_fp32_20260904_104843.json", "results/benchmarks/notebook-controlled/20260904_104755/B01/repeat-02/front_tensorrt_fp32_20260904_104901.json", "results/benchmarks/notebook-controlled/20260904_104755/B01/repeat-03/front_tensorrt_fp32_20260904_104919.json"] | AV2: FALSE | AW2: 0 | AX2: FALSE | AY2: [{"round": 1, "benchmarks": ["results/benchmarks/notebook-controlled/20260904_104755/B01/repeat-01/front_tensorrt_fp32_20260904_104843.json", "results/benchmarks/notebook-controlled/20260904_104755/B01/repeat-02/front_tensorrt_fp32_20260904_104901.json", "results/benchmarks/notebook-controlled/20260904_104755/B01/repeat-03/front_tensorrt_fp32_20260904_104919.json"], "aggregate": {"benchmark_repetitions": 3, "measured_runs_per_repetition": 200, "total_measured_runs": 600, "replicate_median_ms": [45.865366999350954, 45.774185498885345, 45.76235649801674], "replicate_mean_ms": [46.034489404446504, 45.990707429627946, 46.04127945516666], "replicate_median_mean_ms": 45.800636332084345, "replicate_median_std_ms": 0.05636954655638497, "replicate_median_cv": 0.0012307590258718059, "replicate_median_ci95_low_ms": 45.66059531378848, "replicate_median_ci95_high_ms": 45.94067735038021, "mean_ms": 46.02215876308037, "median_ms": 45.82025699710357, "standard_deviation_ms": 1.2844751555142258, "coefficient_of_variation": 0.027909928391813076, "min_ms": 43.22496500390116, "max_ms": 49.91654799960088, "p05_ms": 44.25489459936216, "p25_ms": 45.08433199953288, "p75_ms": 46.6919632472127, "p95_ms": 48.56151670392137, "p99_ms": 49.34060668594611, "iqr_ms": 1.6076312476798194, "fps": 21.728663471610425, "gpu_peak_allocated_bytes": 941561856, "gpu_peak_reserved_bytes": 1000341504}, "official": true}]
A3: B02 | B3: precision | C3: tensorrt-fp16 | D3: fp16 | E3: 1x3x504x504 | F3: 통과 | H3: 완료 | J3: 0.74155301 | K3: 0.92750512 | L3: 0.79308663 | M3: 0.31399164 | N3: 0.63603918 | O3: 0.84685957 | P3: 0.88038199 | Q3: 0.60172169 | R3: 0.83749409 | S3: 0.64879364 | T3: 0.053341953 | U3: 0.48682627 | V3: 0.7146841 | W3: 0.73069235 | X3: 0.71384758 | Y3: 26.039733 | Z3: 25.77521 | AA3: 28.130156 | AB3: 29.321301 | AC3: 1.8137915 | AD3: 0.051220757 | AE3: 0.028758074 | AF3: 24.073147 | AG3: 27.777613 | AH3: 38.402852 | AI3: 941561856 | AJ3: 1000341504 | AK3: 71242972 | AL3: 3 | AM3: 600 | AN3: artifacts/experiments/B02/front/model.engine | AO3: results/coco-evaluation/B02-front.json | AP3: ["results/benchmarks/notebook-controlled/20260904_104755/B02/repeat-01/front_tensorrt_fp16_20260904_104933.json", "results/benchmarks/notebook-controlled/20260904_104755/B02/repeat-02/front_tensorrt_fp16_20260904_104947.json", "results/benchmarks/notebook-controlled/20260904_104755/B02/repeat-03/front_tensorrt_fp16_20260904_105001.json"] | AQ3: 437 | AR3: 86439 | AS3: eedabbb239942a30399e9f1b59b0f8a0c9d76097de80e4efd466535a9b879185 | AT3: 037949731e462ecb42feb6e61b61fbca555dfe2a3d381464ad36a17b0a7ff9b9 | AU3: ["results/benchmarks/notebook-controlled/20260904_104755/B02/repeat-01/front_tensorrt_fp16_20260904_104933.json", "results/benchmarks/notebook-controlled/20260904_104755/B02/repeat-02/front_tensorrt_fp16_20260904_104947.json", "results/benchmarks/notebook-controlled/20260904_104755/B02/repeat-03/front_tensorrt_fp16_20260904_105001.json"] | AV3: FALSE | AW3: 0 | AX3: FALSE | AY3: [{"round": 1, "benchmarks": ["results/benchmarks/notebook-controlled/20260904_104755/B02/repeat-01/front_tensorrt_fp16_20260904_104933.json", "results/benchmarks/notebook-controlled/20260904_104755/B02/repeat-02/front_tensorrt_fp16_20260904_104947.json", "results/benchmarks/notebook-controlled/20260904_104755/B02/repeat-03/front_tensorrt_fp16_20260904_105001.json"], "aggregate": {"benchmark_repetitions": 3, "measured_runs_per_repetition": 200, "total_measured_runs": 600, "replicate_median_ms": [25.510872499580728, 26.78608849964803, 25.4791785046109], "replicate_mean_ms": [25.691386710132065, 26.664797089761123, 25.7630138402601], "replicate_median_mean_ms": 25.92537983461322, "replicate_median_std_ms": 0.7455640025368662, "replicate_median_cv": 0.028758074415614024, "replicate_median_ci95_low_ms": 24.073146696360688, "replicate_median_ci95_high_ms": 27.777612972865754, "mean_ms": 26.03973254671776, "median_ms": 25.775210498977685, "standard_deviation_ms": 1.3337748089065833, "coefficient_of_variation": 0.05122075683817659, "min_ms": 23.657678997551557, "max_ms": 38.57225999672664, "p05_ms": 24.354618451252463, "p25_ms": 25.116360249739955, "p75_ms": 26.930151745546027, "p95_ms": 28.130155548933544, "p99_ms": 29.321301157033297, "iqr_ms": 1.813791495806072, "fps": 38.40285218774443, "gpu_peak_allocated_bytes": 941561856, "gpu_peak_reserved_bytes": 1000341504}, "official": true}]
A4: B03 | B4: precision | C4: tensorrt-int8-ptq | D4: int8 | E4: 1x3x504x504 | F4: 통과 | H4: 완료 | J4: 0.74219013 | K4: 0.92834409 | L4: 0.79528323 | M4: 0.3125477 | N4: 0.63428508 | O4: 0.84784973 | P4: 0.87840454 | Q4: 0.60274983 | R4: 0.83960948 | S4: 0.64742157 | T4: 0.053793733 | U4: 0.48623889 | V4: 0.71519034 | W4: 0.72973293 | X4: 0.71244368 | Y4: 25.695928 | Z4: 25.360001 | AA4: 27.903415 | AB4: 29.424017 | AC4: 1.667965 | AD4: 0.047832669 | AE4: 0.022643032 | AF4: 24.038588 | AG4: 26.904274 | AH4: 38.916672 | AI4: 941561856 | AJ4: 1000341504 | AK4: 71309796 | AL4: 3 | AM4: 600 | AN4: artifacts/experiments/B03/front/model.engine | AO4: results/coco-evaluation/B03-front.json | AP4: ["results/benchmarks/notebook-controlled/20260904_104755/B03/repeat-01/front_tensorrt_int8_20260904_105014.json", "results/benchmarks/notebook-controlled/20260904_104755/B03/repeat-02/front_tensorrt_int8_20260904_105028.json", "results/benchmarks/notebook-controlled/20260904_104755/B03/repeat-03/front_tensorrt_int8_20260904_105042.json"] | AQ4: 437 | AR4: 86420 | AS4: 29efb304dc17c96d4a8b281be1a71eb5e1cf743fb8a87e30aaebe8e6b17d97cf | AT4: 037949731e462ecb42feb6e61b61fbca555dfe2a3d381464ad36a17b0a7ff9b9 | AU4: ["results/benchmarks/notebook-controlled/20260904_104755/B03/repeat-01/front_tensorrt_int8_20260904_105014.json", "results/benchmarks/notebook-controlled/20260904_104755/B03/repeat-02/front_tensorrt_int8_20260904_105028.json", "results/benchmarks/notebook-controlled/20260904_104755/B03/repeat-03/front_tensorrt_int8_20260904_105042.json"] | AV4: FALSE | AW4: 0 | AX4: FALSE | AY4: [{"round": 1, "benchmarks": ["results/benchmarks/notebook-controlled/20260904_104755/B03/repeat-01/front_tensorrt_int8_20260904_105014.json", "results/benchmarks/notebook-controlled/20260904_104755/B03/repeat-02/front_tensorrt_int8_20260904_105028.json", "results/benchmarks/notebook-controlled/20260904_104755/B03/repeat-03/front_tensorrt_int8_20260904_105042.json"], "aggregate": {"benchmark_repetitions": 3, "measured_runs_per_repetition": 200, "total_measured_runs": 600, "replicate_median_ms": [25.11864050029544, 26.1370039988833, 25.15864749875618], "replicate_mean_ms": [25.29866738466808, 26.305342669875245, 25.483774735002953], "replicate_median_mean_ms": 25.471430665978307, "replicate_median_std_ms": 0.5767504105652246, "replicate_median_cv": 0.02264303164311767, "replicate_median_ci95_low_ms": 24.038587584345166, "replicate_median_ci95_high_ms": 26.904273747611448, "mean_ms": 25.695928263182093, "median_ms": 25.360001498484053, "standard_deviation_ms": 1.2291048288609272, "coefficient_of_variation": 0.04783266890661529, "min_ms": 23.745894999592565, "max_ms": 31.56493799906457, "p05_ms": 24.230169856309658, "p25_ms": 24.793393997242674, "p75_ms": 26.461358998858486, "p95_ms": 27.903415251421393, "p99_ms": 29.424016557095452, "iqr_ms": 1.667965001615812, "fps": 38.91667153479839, "gpu_peak_allocated_bytes": 941561856, "gpu_peak_reserved_bytes": 1000341504}, "official": true}]
A5: U01 | B5: unstructured | C5: global-magnitude | D5: fp32 | E5: 1x3x504x504 | F5: 불통 | G5: ONNX 크기·node·dense MACs 중 어느 항목도 사전 고정 5% 감소 기준을 충족하지 못함 | H5: 대기 | AV5: FALSE | AW5: 0 | AX5: FALSE
A6: U02 | B6: unstructured | C6: global-magnitude | D6: fp32 | E6: 1x3x504x504 | F6: 불통 | G6: ONNX 크기·node·dense MACs 중 어느 항목도 사전 고정 5% 감소 기준을 충족하지 못함 | H6: 대기 | AV6: FALSE | AW6: 0 | AX6: FALSE
A7: U03 | B7: unstructured | C7: global-magnitude | D7: fp32 | E7: 1x3x504x504 | F7: 불통 | G7: ONNX 크기·node·dense MACs 중 어느 항목도 사전 고정 5% 감소 기준을 충족하지 못함 | H7: 대기 | AV7: FALSE | AW7: 0 | AX7: FALSE
A8: M01 | B8: semi-structured | C8: nvidia-2to4 | D8: fp16 | E8: 1x3x504x504 | F8: 통과 | H8: 완료 | J8: 0.63458287 | K8: 0.90660321 | L8: 0.69784803 | M8: 0.22404947 | N8: 0.57684388 | O8: 0.73652921 | P8: 0.78770631 | Q8: 0.51798814 | R8: 0.80300658 | S8: 0.55919488 | T8: 0.043139789 | U8: 0.29442734 | V8: 0.63980709 | W8: 0.67737964 | X8: 0.68262358 | Y8: 25.63867 | Z8: 25.386515 | AA8: 27.630042 | AB8: 28.270791 | AC8: 1.279692 | AD8: 0.039698236 | AE8: 0.0095840373 | AF8: 24.793421 | AG8: 26.002881 | AH8: 39.003583 | AI8: 941561856 | AJ8: 1000341504 | AK8: 71198284 | AL8: 3 | AM8: 600 | AN8: artifacts/experiments/M01/front/model.engine | AO8: results/coco-evaluation/M01-front.json | AP8: ["results/benchmarks/notebook-controlled/20260904_104755/M01/repeat-01/front_tensorrt_fp16_20260904_105056.json", "results/benchmarks/notebook-controlled/20260904_104755/M01/repeat-02/front_tensorrt_fp16_20260904_105110.json", "results/benchmarks/notebook-controlled/20260904_104755/M01/repeat-03/front_tensorrt_fp16_20260904_105123.json"] | AQ8: 437 | AR8: 87264 | AS8: 34429486ea34f461cebfd4ed7b2e2df537160c9326589d120e74a962ac39efb7 | AT8: 037949731e462ecb42feb6e61b61fbca555dfe2a3d381464ad36a17b0a7ff9b9 | AU8: ["results/benchmarks/notebook-controlled/20260904_104755/M01/repeat-01/front_tensorrt_fp16_20260904_105056.json", "results/benchmarks/notebook-controlled/20260904_104755/M01/repeat-02/front_tensorrt_fp16_20260904_105110.json", "results/benchmarks/notebook-controlled/20260904_104755/M01/repeat-03/front_tensorrt_fp16_20260904_105123.json"] | AV8: FALSE | AW8: 0 | AX8: FALSE | AY8: [{"round": 1, "benchmarks": ["results/benchmarks/notebook-controlled/20260904_104755/M01/repeat-01/front_tensorrt_fp16_20260904_105056.json", "results/benchmarks/notebook-controlled/20260904_104755/M01/repeat-02/front_tensorrt_fp16_20260904_105110.json", "results/benchmarks/notebook-controlled/20260904_104755/M01/repeat-03/front_tensorrt_fp16_20260904_105123.json"], "aggregate": {"benchmark_repetitions": 3, "measured_runs_per_repetition": 200, "total_measured_runs": 600, "replicate_median_ms": [25.371922998601804, 25.168909996864386, 25.653619501099456], "replicate_mean_ms": [25.636607845262915, 25.308891300082905, 25.970511509622156], "replicate_median_mean_ms": 25.39815083218855, "replicate_median_std_ms": 0.2434168242232701, "replicate_median_cv": 0.009584037272303062, "replicate_median_ci95_low_ms": 24.793421115222046, "replicate_median_ci95_high_ms": 26.00288054915505, "mean_ms": 25.63867021832266, "median_ms": 25.386515499121742, "standard_deviation_ms": 1.0178099691553661, "coefficient_of_variation": 0.03969823553594402, "min_ms": 23.64266099903034, "max_ms": 29.305033000127878, "p05_ms": 24.33986774922232, "p25_ms": 24.924465749791125, "p75_ms": 26.20415775163565, "p95_ms": 27.630041898737545, "p99_ms": 28.270790903407033, "iqr_ms": 1.2796920018445235, "fps": 39.00358292706424, "gpu_peak_allocated_bytes": 941561856, "gpu_peak_reserved_bytes": 1000341504}, "official": true}]
A9: M02 | B9: semi-structured | C9: nvidia-2to4 | D9: fp16 | E9: 1x3x504x504 | F9: 통과 | H9: 완료 | J9: 0.63238036 | K9: 0.90513949 | L9: 0.70029366 | M9: 0.23004445 | N9: 0.64662748 | O9: 0.73405565 | P9: 0.78495606 | Q9: 0.51484803 | R9: 0.79770611 | S9: 0.55857108 | T9: 0.040748802 | U9: 0.30490997 | V9: 0.6389521 | W9: 0.67238182 | X9: 0.67510284 | Y9: 25.62741 | Z9: 25.26247 | AA9: 28.145969 | AB9: 29.207885 | AC9: 1.7020355 | AD9: 0.061994299 | AE9: 0.0057403744 | AF9: 24.899295 | AG9: 25.619748 | AH9: 39.020721 | AI9: 941561856 | AJ9: 1000341504 | AK9: 65423652 | AL9: 3 | AM9: 600 | AN9: artifacts/experiments/M02/front/model.engine | AO9: results/coco-evaluation/M02-front.json | AP9: ["results/benchmarks/notebook-controlled/20260904_104755/M02/repeat-01/front_tensorrt_fp16_20260904_105137.json", "results/benchmarks/notebook-controlled/20260904_104755/M02/repeat-02/front_tensorrt_fp16_20260904_105151.json", "results/benchmarks/notebook-controlled/20260904_104755/M02/repeat-03/front_tensorrt_fp16_20260904_105205.json"] | AQ9: 437 | AR9: 87258 | AS9: 808767d244919a7d37ca5e2509f2480b945e36ea5e8b44fb6f61c2871fc0d5c2 | AT9: 037949731e462ecb42feb6e61b61fbca555dfe2a3d381464ad36a17b0a7ff9b9 | AU9: ["results/benchmarks/notebook-controlled/20260904_104755/M02/repeat-01/front_tensorrt_fp16_20260904_105137.json", "results/benchmarks/notebook-controlled/20260904_104755/M02/repeat-02/front_tensorrt_fp16_20260904_105151.json", "results/benchmarks/notebook-controlled/20260904_104755/M02/repeat-03/front_tensorrt_fp16_20260904_105205.json"] | AV9: FALSE | AW9: 0 | AX9: FALSE | AY9: [{"round": 1, "benchmarks": ["results/benchmarks/notebook-controlled/20260904_104755/M02/repeat-01/front_tensorrt_fp16_20260904_105137.json", "results/benchmarks/notebook-controlled/20260904_104755/M02/repeat-02/front_tensorrt_fp16_20260904_105151.json", "results/benchmarks/notebook-controlled/20260904_104755/M02/repeat-03/front_tensorrt_fp16_20260904_105205.json"], "aggregate": {"benchmark_repetitions": 3, "measured_runs_per_repetition": 200, "total_measured_runs": 600, "replicate_median_ms": [25.14567700200132, 25.21012199940742, 25.422765498660738], "replicate_mean_ms": [25.743770000008226, 25.47602516027837, 25.662433544785017], "replicate_median_mean_ms": 25.25952150002316, "replicate_median_std_ms": 0.14499910944918673, "replicate_median_cv": 0.005740374355430834, "replicate_median_ci95_low_ms": 24.89929467224574, "replicate_median_ci95_high_ms": 25.619748327800576, "mean_ms": 25.627409568357205, "median_ms": 25.26247049900121, "standard_deviation_ms": 1.5887532945822038, "coefficient_of_variation": 0.061994299125100676, "min_ms": 23.210936000396032, "max_ms": 40.46235499845352, "p05_ms": 23.92078685297747, "p25_ms": 24.66518025175901, "p75_ms": 26.367215750724426, "p95_ms": 28.145969146498825, "p99_ms": 29.207884659335832, "iqr_ms": 1.7020354989654152, "fps": 39.020721049962255, "gpu_peak_allocated_bytes": 941561856, "gpu_peak_reserved_bytes": 1000341504}, "official": true}]
A10: S01 | B10: structured | C10: decoder-layer | D10: fp32 | E10: 1x3x504x504 | F10: 통과 | H10: 완료 | J10: 0.73899927 | K10: 0.9339003 | L10: 0.79073244 | M10: 0.28278597 | N10: 0.56241361 | O10: 0.84483168 | P10: 0.87360582 | Q10: 0.60223001 | R10: 0.84376734 | S10: 0.65914725 | T10: 0.055606099 | U10: 0.45515441 | V10: 0.71089764 | W10: 0.73131768 | X10: 0.73389948 | Y10: 44.677144 | Z10: 44.509862 | AA10: 46.953992 | AB10: 47.977664 | AC10: 1.9196855 | AD10: 0.02909475 | AE10: 0.011642105 | AF10: 43.25049 | AG10: 45.826868 | AH10: 22.382809 | AI10: 941561856 | AJ10: 1000341504 | AK10: 129241676 | AL10: 3 | AM10: 600 | AN10: artifacts/experiments/S01/front/model.engine | AO10: results/coco-evaluation/S01-front.json | AP10: ["results/benchmarks/notebook-controlled/20260904_104755/S01/repeat-01/front_tensorrt_fp32_20260904_105223.json", "results/benchmarks/notebook-controlled/20260904_104755/S01/repeat-02/front_tensorrt_fp32_20260904_105241.json", "results/benchmarks/notebook-controlled/20260904_104755/S01/repeat-03/front_tensorrt_fp32_20260904_105259.json"] | AQ10: 437 | AR10: 87120 | AS10: 1657f1292a20ef0ad02f1c733c8e8056038a6d6de5bed2e6d75eb385142cbb90 | AT10: 037949731e462ecb42feb6e61b61fbca555dfe2a3d381464ad36a17b0a7ff9b9 | AU10: ["results/benchmarks/notebook-controlled/20260904_104755/S01/repeat-01/front_tensorrt_fp32_20260904_105223.json", "results/benchmarks/notebook-controlled/20260904_104755/S01/repeat-02/front_tensorrt_fp32_20260904_105241.json", "results/benchmarks/notebook-controlled/20260904_104755/S01/repeat-03/front_tensorrt_fp32_20260904_105259.json"] | AV10: FALSE | AW10: 0 | AX10: FALSE | AY10: [{"round": 1, "benchmarks": ["results/benchmarks/notebook-controlled/20260904_104755/S01/repeat-01/front_tensorrt_fp32_20260904_105223.json", "results/benchmarks/notebook-controlled/20260904_104755/S01/repeat-02/front_tensorrt_fp32_20260904_105241.json", "results/benchmarks/notebook-controlled/20260904_104755/S01/repeat-03/front_tensorrt_fp32_20260904_105259.json"], "aggregate": {"benchmark_repetitions": 3, "measured_runs_per_repetition": 200, "total_measured_runs": 600, "replicate_median_ms": [44.887716496305075, 44.785463502194034, 43.942856496869354], "replicate_mean_ms": [44.94487110005139, 44.91223885968793, 44.17432209447725], "replicate_median_mean_ms": 44.53867883178949, "replicate_median_std_ms": 0.5185239722456698, "replicate_median_cv": 0.011642104926461654, "replicate_median_ci95_low_ms": 43.25048991560818, "replicate_median_ci95_high_ms": 45.8268677479708, "mean_ms": 44.67714401807219, "median_ms": 44.509862000268186, "standard_deviation_ms": 1.299870323100578, "coefficient_of_variation": 0.029094749713069665, "min_ms": 42.054261997691356, "max_ms": 48.99946499790531, "p05_ms": 42.835195003135595, "p25_ms": 43.685598249794566, "p75_ms": 45.60528374895512, "p95_ms": 46.95399169904703, "p99_ms": 47.97766403615241, "iqr_ms": 1.9196854991605505, "fps": 22.38280942030434, "gpu_peak_allocated_bytes": 941561856, "gpu_peak_reserved_bytes": 1000341504}, "official": true}]
A11: S02 | B11: structured | C11: decoder-layer | D11: fp32 | E11: 1x3x504x504 | F11: 통과 | H11: 완료 | J11: 0.71612133 | K11: 0.92452324 | L11: 0.77508703 | M11: 0.30498342 | N11: 0.63020013 | O11: 0.82107551 | P11: 0.87556548 | Q11: 0.58504198 | R11: 0.82465115 | S11: 0.63859494 | T11: 0.050396645 | U11: 0.44880398 | V11: 0.70597976 | W11: 0.72410241 | X11: 0.75312865 | Y11: 43.109538 | Z11: 42.957116 | AA11: 45.106497 | AB11: 45.978702 | AC11: 1.0655317 | AD11: 0.022827765 | AE11: 0.0055514941 | AF11: 42.34599 | AG11: 43.530379 | AH11: 23.196722 | AI11: 941561856 | AJ11: 1000341504 | AK11: 122879868 | AL11: 3 | AM11: 600 | AN11: artifacts/experiments/S02/front/model.engine | AO11: results/coco-evaluation/S02-front.json | AP11: ["results/benchmarks/notebook-controlled/20260904_104755/S02/repeat-01/front_tensorrt_fp32_20260904_105316.json", "results/benchmarks/notebook-controlled/20260904_104755/S02/repeat-02/front_tensorrt_fp32_20260904_105334.json", "results/benchmarks/notebook-controlled/20260904_104755/S02/repeat-03/front_tensorrt_fp32_20260904_105352.json"] | AQ11: 437 | AR11: 85836 | AS11: a5a26d9f974c0e14adc550ab7644919652b2b08025f2b335d3af05e7c220902d | AT11: 037949731e462ecb42feb6e61b61fbca555dfe2a3d381464ad36a17b0a7ff9b9 | AU11: ["results/benchmarks/notebook-controlled/20260904_104755/S02/repeat-01/front_tensorrt_fp32_20260904_105316.json", "results/benchmarks/notebook-controlled/20260904_104755/S02/repeat-02/front_tensorrt_fp32_20260904_105334.json", "results/benchmarks/notebook-controlled/20260904_104755/S02/repeat-03/front_tensorrt_fp32_20260904_105352.json"] | AV11: FALSE | AW11: 0 | AX11: FALSE | AY11: [{"round": 1, "benchmarks": ["results/benchmarks/notebook-controlled/20260904_104755/S02/repeat-01/front_tensorrt_fp32_20260904_105316.json", "results/benchmarks/notebook-controlled/20260904_104755/S02/repeat-02/front_tensorrt_fp32_20260904_105334.json", "results/benchmarks/notebook-controlled/20260904_104755/S02/repeat-03/front_tensorrt_fp32_20260904_105352.json"], "aggregate": {"benchmark_repetitions": 3, "measured_runs_per_repetition": 200, "total_measured_runs": 600, "replicate_median_ms": [42.77670200099237, 43.21196299861185, 42.82588899877737], "replicate_mean_ms": [43.038969919907686, 43.425512820103904, 42.86413266509044], "replicate_median_mean_ms": 42.9381846661272, "replicate_median_std_ms": 0.23837107981324704, "replicate_median_cv": 0.005551494122696149, "replicate_median_ci95_low_ms": 42.345990284787945, "replicate_median_ci95_high_ms": 43.530379047466454, "mean_ms": 43.10953846836734, "median_ms": 42.95711550003034, "standard_deviation_ms": 0.9840944162029024, "coefficient_of_variation": 0.022827765064685285, "min_ms": 40.98106099991128, "max_ms": 46.70429600082571, "p05_ms": 41.72241199739801, "p25_ms": 42.4860395014548, "p75_ms": 43.551571248826804, "p95_ms": 45.106496605149005, "p99_ms": 45.978701640851796, "iqr_ms": 1.065531747372006, "fps": 23.196722477875145, "gpu_peak_allocated_bytes": 941561856, "gpu_peak_reserved_bytes": 1000341504}, "official": true}]
A12: S03 | B12: structured | C12: ffn-dimension | D12: fp32 | E12: 1x3x504x504 | F12: 불통 | G12: ONNX 크기·node·dense MACs 중 어느 항목도 사전 고정 5% 감소 기준을 충족하지 못함 | H12: 대기 | AV12: FALSE | AW12: 0 | AX12: FALSE
A13: S04 | B13: structured | C13: ffn-dimension | D13: fp32 | E13: 1x3x504x504 | F13: 통과 | H13: 완료 | J13: 0.51805164 | K13: 0.85895357 | L13: 0.58459714 | M13: 0.16141184 | N13: 0.37367497 | O13: 0.58421797 | P13: 0.72048251 | Q13: 0.52135 | R13: 0.79650539 | S13: 0.55469888 | T13: 0.043461002 | U13: 0.34367292 | V13: 0.62493594 | W13: 0.71266109 | X13: 0.64755762 | Y13: 45.889984 | Z13: 45.768655 | AA13: 48.07663 | AB13: 48.893656 | AC13: 1.6223143 | AD13: 0.025502928 | AE13: 0.0057996725 | AF13: 45.099383 | AG13: 46.417997 | AH13: 21.791248 | AI13: 941561856 | AJ13: 1000341504 | AK13: 127079372 | AL13: 3 | AM13: 600 | AN13: artifacts/experiments/S04/front/model.engine | AO13: results/coco-evaluation/S04-front.json | AP13: ["results/benchmarks/notebook-controlled/20260904_104755/S04/repeat-01/front_tensorrt_fp32_20260904_105410.json", "results/benchmarks/notebook-controlled/20260904_104755/S04/repeat-02/front_tensorrt_fp32_20260904_105428.json", "results/benchmarks/notebook-controlled/20260904_104755/S04/repeat-03/front_tensorrt_fp32_20260904_105446.json"] | AQ13: 437 | AR13: 83756 | AS13: 0be2db8272e6055f37e30e3b3a809704ffccf615e40e8c5ad0726370bb089c04 | AT13: 037949731e462ecb42feb6e61b61fbca555dfe2a3d381464ad36a17b0a7ff9b9 | AU13: ["results/benchmarks/notebook-controlled/20260904_104755/S04/repeat-01/front_tensorrt_fp32_20260904_105410.json", "results/benchmarks/notebook-controlled/20260904_104755/S04/repeat-02/front_tensorrt_fp32_20260904_105428.json", "results/benchmarks/notebook-controlled/20260904_104755/S04/repeat-03/front_tensorrt_fp32_20260904_105446.json"] | AV13: FALSE | AW13: 0 | AX13: FALSE | AY13: [{"round": 1, "benchmarks": ["results/benchmarks/notebook-controlled/20260904_104755/S04/repeat-01/front_tensorrt_fp32_20260904_105410.json", "results/benchmarks/notebook-controlled/20260904_104755/S04/repeat-02/front_tensorrt_fp32_20260904_105428.json", "results/benchmarks/notebook-controlled/20260904_104755/S04/repeat-03/front_tensorrt_fp32_20260904_105446.json"], "aggregate": {"benchmark_repetitions": 3, "measured_runs_per_repetition": 200, "total_measured_runs": 600, "replicate_median_ms": [46.064877500612056, 45.616389495990006, 45.5948039998475], "replicate_mean_ms": [46.13614516980306, 45.72785710995959, 45.8059498050352], "replicate_median_mean_ms": 45.758690332149854, "replicate_median_std_ms": 0.26538541785317665, "replicate_median_cv": 0.005799672497766354, "replicate_median_ci95_low_ms": 45.099383198645455, "replicate_median_ci95_high_ms": 46.41799746565425, "mean_ms": 45.88998402826595, "median_ms": 45.76865499984706, "standard_deviation_ms": 1.17032895773334, "coefficient_of_variation": 0.025502927981244785, "min_ms": 43.30192100314889, "max_ms": 49.49725999904331, "p05_ms": 44.24601095051912, "p25_ms": 44.998984749327064, "p75_ms": 46.621299004982575, "p95_ms": 48.07662969978992, "p99_ms": 48.893655821011635, "iqr_ms": 1.6223142556555104, "fps": 21.791247505862056, "gpu_peak_allocated_bytes": 941561856, "gpu_peak_reserved_bytes": 1000341504}, "official": true}]
A14: C01 | B14: combined | C14: structured-selected | D14: fp16 | E14: 1x3x504x504 | F14: 통과 | H14: 완료 | J14: 0.7385979 | K14: 0.93594106 | L14: 0.79249168 | M14: 0.27793136 | N14: 0.55671151 | O14: 0.84176603 | P14: 0.87522966 | Q14: 0.60291193 | R14: 0.84149258 | S14: 0.65624343 | T14: 0.055714564 | U14: 0.44831251 | V14: 0.71328817 | W14: 0.73357226 | X14: 0.73668954 | Y14: 25.554921 | Z14: 25.29961 | AA14: 27.511682 | AB14: 28.201303 | AC14: 1.7426035 | AD14: 0.043754441 | AE14: 0.029110828 | AF14: 23.598337 | AG14: 27.277753 | AH14: 39.131406 | AI14: 941561856 | AJ14: 1000341504 | AK14: 67873396 | AL14: 3 | AM14: 600 | AN14: artifacts/experiments/C01/front/model.engine | AO14: results/coco-evaluation/C01-front.json | AP14: ["results/benchmarks/notebook-controlled/20260904_104755/C01/repeat-01/front_tensorrt_fp16_20260904_105500.json", "results/benchmarks/notebook-controlled/20260904_104755/C01/repeat-02/front_tensorrt_fp16_20260904_105514.json", "results/benchmarks/notebook-controlled/20260904_104755/C01/repeat-03/front_tensorrt_fp16_20260904_105528.json"] | AQ14: 437 | AR14: 87115 | AS14: bfbcd85bff8b8eb57c2be2368c5cba41aebe25c9892603894a59fc184ff035f6 | AT14: 037949731e462ecb42feb6e61b61fbca555dfe2a3d381464ad36a17b0a7ff9b9 | AU14: ["results/benchmarks/notebook-controlled/20260904_104755/C01/repeat-01/front_tensorrt_fp16_20260904_105500.json", "results/benchmarks/notebook-controlled/20260904_104755/C01/repeat-02/front_tensorrt_fp16_20260904_105514.json", "results/benchmarks/notebook-controlled/20260904_104755/C01/repeat-03/front_tensorrt_fp16_20260904_105528.json"] | AV14: FALSE | AW14: 0 | AX14: FALSE | AY14: [{"round": 1, "benchmarks": ["results/benchmarks/notebook-controlled/20260904_104755/C01/repeat-01/front_tensorrt_fp16_20260904_105500.json", "results/benchmarks/notebook-controlled/20260904_104755/C01/repeat-02/front_tensorrt_fp16_20260904_105514.json", "results/benchmarks/notebook-controlled/20260904_104755/C01/repeat-03/front_tensorrt_fp16_20260904_105528.json"], "aggregate": {"benchmark_repetitions": 3, "measured_runs_per_repetition": 200, "total_measured_runs": 600, "replicate_median_ms": [25.126939501205925, 24.903826997615397, 26.283368501026416], "replicate_mean_ms": [25.403895925119286, 25.07744679973257, 26.183420429952093], "replicate_median_mean_ms": 25.438044999949245, "replicate_median_std_ms": 0.7405225610470161, "replicate_median_cv": 0.029110828330105306, "replicate_median_ci95_low_ms": 23.59833650741497, "replicate_median_ci95_high_ms": 27.27775349248352, "mean_ms": 25.554921051601315, "median_ms": 25.29960950050736, "standard_deviation_ms": 1.1181412929326209, "coefficient_of_variation": 0.04375444129429452, "min_ms": 23.53737199882744, "max_ms": 30.649074004031718, "p05_ms": 24.09362330181466, "p25_ms": 24.682271001438494, "p75_ms": 26.424874498843565, "p95_ms": 27.511681694886644, "p99_ms": 28.20130314830749, "iqr_ms": 1.7426034974050708, "fps": 39.13140635342868, "gpu_peak_allocated_bytes": 941561856, "gpu_peak_reserved_bytes": 1000341504}, "official": true}]
A15: C02 | B15: combined | C15: structured-selected | D15: int8 | E15: 1x3x504x504 | F15: 통과 | H15: 완료 | J15: 0.74008636 | K15: 0.93562937 | L15: 0.79462468 | M15: 0.28070259 | N15: 0.56672462 | O15: 0.84203029 | P15: 0.87501649 | Q15: 0.6023426 | R15: 0.84365199 | S15: 0.65402347 | T15: 0.054740426 | U15: 0.45577144 | V15: 0.70876026 | W15: 0.73419945 | X15: 0.74121123 | Y15: 26.001112 | Z15: 26.182796 | AA15: 27.425262 | AB15: 27.946538 | AC15: 1.3991685 | AD15: 0.038013553 | AE15: 0.0084948439 | AF15: 25.581456 | AG15: 26.68448 | AH15: 38.459894 | AI15: 941561856 | AJ15: 1000341504 | AK15: 67959596 | AL15: 3 | AM15: 600 | AN15: artifacts/experiments/C02/front/model.engine | AO15: results/coco-evaluation/C02-front.json | AP15: ["results/benchmarks/notebook-controlled/20260904_104755/C02/repeat-01/front_tensorrt_int8_20260904_105542.json", "results/benchmarks/notebook-controlled/20260904_104755/C02/repeat-02/front_tensorrt_int8_20260904_105556.json", "results/benchmarks/notebook-controlled/20260904_104755/C02/repeat-03/front_tensorrt_int8_20260904_105610.json"] | AQ15: 437 | AR15: 87107 | AS15: 828a0f74ef4b9629f999a99c3c955e97d69cc52306bf44aeea69f7f8d128c6e3 | AT15: 037949731e462ecb42feb6e61b61fbca555dfe2a3d381464ad36a17b0a7ff9b9 | AU15: ["results/benchmarks/notebook-controlled/20260904_104755/C02/repeat-01/front_tensorrt_int8_20260904_105542.json", "results/benchmarks/notebook-controlled/20260904_104755/C02/repeat-02/front_tensorrt_int8_20260904_105556.json", "results/benchmarks/notebook-controlled/20260904_104755/C02/repeat-03/front_tensorrt_int8_20260904_105610.json"] | AV15: FALSE | AW15: 0 | AX15: FALSE | AY15: [{"round": 1, "benchmarks": ["results/benchmarks/notebook-controlled/20260904_104755/C02/repeat-01/front_tensorrt_int8_20260904_105542.json", "results/benchmarks/notebook-controlled/20260904_104755/C02/repeat-02/front_tensorrt_int8_20260904_105556.json", "results/benchmarks/notebook-controlled/20260904_104755/C02/repeat-03/front_tensorrt_int8_20260904_105610.json"], "aggregate": {"benchmark_repetitions": 3, "measured_runs_per_repetition": 200, "total_measured_runs": 600, "replicate_median_ms": [26.37079200212611, 26.096891997440252, 25.931219999620225], "replicate_mean_ms": [26.136388615232136, 25.966977779717126, 25.89996900955157], "replicate_median_mean_ms": 26.132967999728862, "replicate_median_std_ms": 0.22199548374371034, "replicate_median_cv": 0.008494843897792766, "replicate_median_ci95_low_ms": 25.581456137389225, "replicate_median_ci95_high_ms": 26.6844798620685, "mean_ms": 26.001111801500276, "median_ms": 26.182795998465735, "standard_deviation_ms": 0.9883946343311655, "coefficient_of_variation": 0.03801355272331603, "min_ms": 23.30352699937066, "max_ms": 28.45742699719267, "p05_ms": 24.24414754859754, "p25_ms": 25.30518849926011, "p75_ms": 26.70435699656082, "p95_ms": 27.425261502867215, "p99_ms": 27.946537816678756, "iqr_ms": 1.3991684973007068, "fps": 38.4598938550889, "gpu_peak_allocated_bytes": 941561856, "gpu_peak_reserved_bytes": 1000341504}, "official": true}]
A16: C03 | B16: combined | C16: structured-resolution | D16: fp32 | E16: 1x3x432x432 | F16: 통과 | H16: 완료 | J16: 0.73188194 | K16: 0.93222023 | L16: 0.79208795 | M16: 0.26436114 | N16: 0.59308767 | O16: 0.84334965 | P16: 0.8670514 | Q16: 0.59399273 | R16: 0.83894636 | S16: 0.65198455 | T16: 0.044845135 | U16: 0.46374766 | V16: 0.7018798 | W16: 0.71774164 | X16: 0.73530641 | Y16: 36.208961 | Z16: 36.296055 | AA16: 37.833982 | AB16: 38.435298 | AC16: 1.5360317 | AD16: 0.030690624 | AE16: 0.0048770809 | AF16: 35.864611 | AG16: 36.744365 | AH16: 27.617473 | AI16: 936573952 | AJ16: 977272832 | AK16: 128549228 | AL16: 3 | AM16: 600 | AN16: artifacts/experiments/C03/front/model.engine | AO16: results/coco-evaluation/C03-front.json | AP16: ["results/benchmarks/notebook-controlled/20260904_104755/C03/repeat-01/front_tensorrt_fp32_20260904_105626.json", "results/benchmarks/notebook-controlled/20260904_104755/C03/repeat-02/front_tensorrt_fp32_20260904_105642.json", "results/benchmarks/notebook-controlled/20260904_104755/C03/repeat-03/front_tensorrt_fp32_20260904_105658.json"] | AQ16: 437 | AR16: 87063 | AS16: 633b6f87ea21ef96eace52901791958a66b13f87022fc86b1e4d4873afdb3ecf | AT16: 037949731e462ecb42feb6e61b61fbca555dfe2a3d381464ad36a17b0a7ff9b9 | AU16: ["results/benchmarks/notebook-controlled/20260904_104755/C03/repeat-01/front_tensorrt_fp32_20260904_105626.json", "results/benchmarks/notebook-controlled/20260904_104755/C03/repeat-02/front_tensorrt_fp32_20260904_105642.json", "results/benchmarks/notebook-controlled/20260904_104755/C03/repeat-03/front_tensorrt_fp32_20260904_105658.json"] | AV16: FALSE | AW16: 0 | AX16: FALSE | AY16: [{"round": 1, "benchmarks": ["results/benchmarks/notebook-controlled/20260904_104755/C03/repeat-01/front_tensorrt_fp32_20260904_105626.json", "results/benchmarks/notebook-controlled/20260904_104755/C03/repeat-02/front_tensorrt_fp32_20260904_105642.json", "results/benchmarks/notebook-controlled/20260904_104755/C03/repeat-03/front_tensorrt_fp32_20260904_105658.json"], "aggregate": {"benchmark_repetitions": 3, "measured_runs_per_repetition": 200, "total_measured_runs": 600, "replicate_median_ms": [36.10285100148758, 36.376029001985444, 36.43458350052242], "replicate_mean_ms": [36.078320195192646, 36.23329845006083, 36.31526332505018], "replicate_median_mean_ms": 36.304487834665146, "replicate_median_std_ms": 0.17705992402330442, "replicate_median_cv": 0.00487708089505782, "replicate_median_ci95_low_ms": 35.86461110025129, "replicate_median_ci95_high_ms": 36.744364569079, "mean_ms": 36.208960656767886, "median_ms": 36.29605549576809, "standard_deviation_ms": 1.1112755853658471, "coefficient_of_variation": 0.030690623680139698, "min_ms": 33.22450899577234, "max_ms": 39.55846199824009, "p05_ms": 34.21704210122698, "p25_ms": 35.46080725027423, "p75_ms": 36.99683899867523, "p95_ms": 37.83398185187252, "p99_ms": 38.435297518444706, "iqr_ms": 1.536031748401001, "fps": 27.617473185137893, "gpu_peak_allocated_bytes": 936573952, "gpu_peak_reserved_bytes": 977272832}, "official": true}]
A17: C04 | B17: combined | C17: structured-resolution | D17: fp32 | E17: 1x3x480x480 | F17: 통과 | H17: 완료 | J17: 0.73104154 | K17: 0.93647209 | L17: 0.78319446 | M17: 0.27018859 | N17: 0.47927881 | O17: 0.84405154 | P17: 0.87169048 | Q17: 0.59960567 | R17: 0.84427601 | S17: 0.64571835 | T17: 0.043581685 | U17: 0.37218581 | V17: 0.70641035 | W17: 0.72764179 | X17: 0.72817834 | Y17: 41.760352 | Z17: 41.973261 | AA17: 43.175509 | AB17: 43.628503 | AC17: 1.3155025 | AD17: 0.023762424 | AE17: 0.0025527561 | AF17: 41.689412 | AG17: 42.221568 | AH17: 23.946158 | AI17: 939813376 | AJ17: 981467136 | AK17: 128969140 | AL17: 3 | AM17: 600 | AN17: artifacts/experiments/C04/front/model.engine | AO17: results/coco-evaluation/C04-front.json | AP17: ["results/benchmarks/notebook-controlled/20260904_104755/C04/repeat-01/front_tensorrt_fp32_20260904_105715.json", "results/benchmarks/notebook-controlled/20260904_104755/C04/repeat-02/front_tensorrt_fp32_20260904_105733.json", "results/benchmarks/notebook-controlled/20260904_104755/C04/repeat-03/front_tensorrt_fp32_20260904_105750.json"] | AQ17: 437 | AR17: 87129 | AS17: 14de81813ff71cac78d0d349431099c5119905068ce3f85da70404280a86a551 | AT17: 037949731e462ecb42feb6e61b61fbca555dfe2a3d381464ad36a17b0a7ff9b9 | AU17: ["results/benchmarks/notebook-controlled/20260904_104755/C04/repeat-01/front_tensorrt_fp32_20260904_105715.json", "results/benchmarks/notebook-controlled/20260904_104755/C04/repeat-02/front_tensorrt_fp32_20260904_105733.json", "results/benchmarks/notebook-controlled/20260904_104755/C04/repeat-03/front_tensorrt_fp32_20260904_105750.json"] | AV17: FALSE | AW17: 0 | AX17: FALSE | AY17: [{"round": 1, "benchmarks": ["results/benchmarks/notebook-controlled/20260904_104755/C04/repeat-01/front_tensorrt_fp32_20260904_105715.json", "results/benchmarks/notebook-controlled/20260904_104755/C04/repeat-02/front_tensorrt_fp32_20260904_105733.json", "results/benchmarks/notebook-controlled/20260904_104755/C04/repeat-03/front_tensorrt_fp32_20260904_105750.json"], "aggregate": {"benchmark_repetitions": 3, "measured_runs_per_repetition": 200, "total_measured_runs": 600, "replicate_median_ms": [42.05381450083223, 41.9712895018165, 41.8413654952019], "replicate_mean_ms": [41.932456035101495, 41.67228156456986, 41.67631771986635], "replicate_median_mean_ms": 41.95548983261688, "replicate_median_std_ms": 0.10710213423850365, "replicate_median_cv": 0.0025527561390843475, "replicate_median_ci95_low_ms": 41.68941190833523, "replicate_median_ci95_high_ms": 42.22156775689852, "mean_ms": 41.76035177317923, "median_ms": 41.97326050052652, "standard_deviation_ms": 0.9923271832611434, "coefficient_of_variation": 0.023762423953010616, "min_ms": 38.95193499920424, "max_ms": 44.69248000532389, "p05_ms": 39.830163451551925, "p25_ms": 41.14152350302902, "p75_ms": 42.457026000192855, "p95_ms": 43.17550875166489, "p99_ms": 43.628503036961774, "iqr_ms": 1.315502497163834, "fps": 23.94615843830737, "gpu_peak_allocated_bytes": 939813376, "gpu_peak_reserved_bytes": 981467136}, "official": true}]
A18: R01 | B18: input | C18: input-resolution | D18: fp16 | E18: 1x3x432x432 | F18: 통과 | H18: 완료 | J18: 0.72879848 | K18: 0.92463003 | L18: 0.78037428 | M18: 0.27496726 | N18: 0.53420588 | O18: 0.84300686 | P18: 0.86792373 | Q18: 0.5941088 | R18: 0.83268645 | S18: 0.6361196 | T18: 0.046705593 | U18: 0.52569503 | V18: 0.7109113 | W18: 0.71422209 | X18: 0.70343888 | Y18: 24.105135 | Z18: 24.010296 | AA18: 25.820945 | AB18: 26.43698 | AC18: 1.9596793 | AD18: 0.046791008 | AE18: 0.038248698 | AF18: 21.728277 | AG18: 26.291219 | AH18: 41.484937 | AI18: 936573952 | AJ18: 977272832 | AK18: 71359388 | AL18: 3 | AM18: 600 | AN18: artifacts/experiments/R01/front/model.engine | AO18: results/coco-evaluation/R01-front.json | AP18: ["results/benchmarks/notebook-controlled/20260904_104755/R01/repeat-01/front_tensorrt_fp16_20260904_105803.json", "results/benchmarks/notebook-controlled/20260904_104755/R01/repeat-02/front_tensorrt_fp16_20260904_105817.json", "results/benchmarks/notebook-controlled/20260904_104755/R01/repeat-03/front_tensorrt_fp16_20260904_105830.json"] | AQ18: 437 | AR18: 86457 | AS18: 9c4cef49331dc94581f92ff10a141a5619caaf3c71aa708c24bfc0a39311efda | AT18: 037949731e462ecb42feb6e61b61fbca555dfe2a3d381464ad36a17b0a7ff9b9 | AU18: ["results/benchmarks/notebook-controlled/20260904_104755/R01/repeat-01/front_tensorrt_fp16_20260904_105803.json", "results/benchmarks/notebook-controlled/20260904_104755/R01/repeat-02/front_tensorrt_fp16_20260904_105817.json", "results/benchmarks/notebook-controlled/20260904_104755/R01/repeat-03/front_tensorrt_fp16_20260904_105830.json"] | AV18: FALSE | AW18: 0 | AX18: FALSE | AY18: [{"round": 1, "benchmarks": ["results/benchmarks/notebook-controlled/20260904_104755/R01/repeat-01/front_tensorrt_fp16_20260904_105803.json", "results/benchmarks/notebook-controlled/20260904_104755/R01/repeat-02/front_tensorrt_fp16_20260904_105817.json", "results/benchmarks/notebook-controlled/20260904_104755/R01/repeat-03/front_tensorrt_fp16_20260904_105830.json"], "aggregate": {"benchmark_repetitions": 3, "measured_runs_per_repetition": 200, "total_measured_runs": 600, "replicate_median_ms": [23.208815502584912, 25.012070997036062, 23.808357000234537], "replicate_mean_ms": [23.409623375155206, 24.883610060423962, 24.0221716951055], "replicate_median_mean_ms": 24.00974783328517, "replicate_median_std_ms": 0.9183416005467065, "replicate_median_cv": 0.03824869827552258, "replicate_median_ci95_low_ms": 21.728276706754528, "replicate_median_ci95_high_ms": 26.291218959815815, "mean_ms": 24.105135043561557, "median_ms": 24.010295503103407, "standard_deviation_ms": 1.1279035651392872, "coefficient_of_variation": 0.046791007936732076, "min_ms": 21.792273000755813, "max_ms": 26.894788999925368, "p05_ms": 22.4953793505847, "p25_ms": 23.13907899770129, "p75_ms": 25.098758251260733, "p95_ms": 25.820945401574136, "p99_ms": 26.436979941063328, "iqr_ms": 1.9596792535594432, "fps": 41.484936640796725, "gpu_peak_allocated_bytes": 936573952, "gpu_peak_reserved_bytes": 977272832}, "official": true}]
A19: R02 | B19: input | C19: input-resolution | D19: fp32 | E19: 1x3x480x480 | F19: 통과 | H19: 완료 | J19: 0.73297313 | K19: 0.92523759 | L19: 0.77896569 | M19: 0.27543083 | N19: 0.51638202 | O19: 0.84479471 | P19: 0.87819664 | Q19: 0.59972689 | R19: 0.84129617 | S19: 0.6382844 | T19: 0.050045714 | U19: 0.3898645 | V19: 0.70859361 | W19: 0.72718339 | X19: 0.71075491 | Y19: 42.840242 | Z19: 42.962943 | AA19: 44.720605 | AB19: 45.705335 | AC19: 1.8500425 | AD19: 0.030021731 | AE19: 0.012593398 | AF19: 41.474829 | AG19: 44.15383 | AH19: 23.342539 | AI19: 939813376 | AJ19: 981467136 | AK19: 135359412 | AL19: 3 | AM19: 600 | AN19: artifacts/experiments/R02/front/model.engine | AO19: results/coco-evaluation/R02-front.json | AP19: ["results/benchmarks/notebook-controlled/20260904_104755/R02/repeat-01/front_tensorrt_fp32_20260904_105848.json", "results/benchmarks/notebook-controlled/20260904_104755/R02/repeat-02/front_tensorrt_fp32_20260904_105905.json", "results/benchmarks/notebook-controlled/20260904_104755/R02/repeat-03/front_tensorrt_fp32_20260904_105924.json"] | AQ19: 437 | AR19: 86477 | AS19: ff5c45209c42a5a49a130e6694eed0af947c9d7c2a667ebf5d4b0a2b56cd2a31 | AT19: 037949731e462ecb42feb6e61b61fbca555dfe2a3d381464ad36a17b0a7ff9b9 | AU19: ["results/benchmarks/notebook-controlled/20260904_104755/R02/repeat-01/front_tensorrt_fp32_20260904_105848.json", "results/benchmarks/notebook-controlled/20260904_104755/R02/repeat-02/front_tensorrt_fp32_20260904_105905.json", "results/benchmarks/notebook-controlled/20260904_104755/R02/repeat-03/front_tensorrt_fp32_20260904_105924.json"] | AV19: FALSE | AW19: 0 | AX19: FALSE | AY19: [{"round": 1, "benchmarks": ["results/benchmarks/notebook-controlled/20260904_104755/R02/repeat-01/front_tensorrt_fp32_20260904_105848.json", "results/benchmarks/notebook-controlled/20260904_104755/R02/repeat-02/front_tensorrt_fp32_20260904_105905.json", "results/benchmarks/notebook-controlled/20260904_104755/R02/repeat-03/front_tensorrt_fp32_20260904_105924.json"], "aggregate": {"benchmark_repetitions": 3, "measured_runs_per_repetition": 200, "total_measured_runs": 600, "replicate_median_ms": [43.12465450129821, 42.1917415005737, 43.12659249626449], "replicate_mean_ms": [43.07042928507144, 42.383735650073504, 43.066560674888024], "replicate_median_mean_ms": 42.8143294993788, "replicate_median_std_ms": 0.539177893786669, "replicate_median_cv": 0.01259339805367014, "replicate_median_ci95_low_ms": 41.47482925676148, "replicate_median_ci95_high_ms": 44.15382974199612, "mean_ms": 42.84024187001099, "median_ms": 42.96294300002046, "standard_deviation_ms": 1.2861382243507, "coefficient_of_variation": 0.030021731162330853, "min_ms": 39.765353001712356, "max_ms": 47.83193000184838, "p05_ms": 40.673409801820526, "p25_ms": 41.94262375312974, "p75_ms": 43.79266624709999, "p95_ms": 44.72060505286208, "p99_ms": 45.70533483325562, "iqr_ms": 1.8500424939702498, "fps": 23.342538612043167, "gpu_peak_allocated_bytes": 939813376, "gpu_peak_reserved_bytes": 981467136}, "official": true}]
A20: R03 | B20: input | C20: input-resolution | D20: fp32 | E20: 1x3x384x384 | F20: 통과 | H20: 완료 | J20: 0.72645641 | K20: 0.93295052 | L20: 0.76678196 | M20: 0.23783456 | N20: 0.54447076 | O20: 0.84602563 | P20: 0.86805852 | Q20: 0.58654093 | R20: 0.81565952 | S20: 0.63881967 | T20: 0.031683889 | U20: 0.34485719 | V20: 0.70257232 | W20: 0.70189516 | X20: 0.7281028 | Y20: 32.546984 | Z20: 32.38641 | AA20: 34.875149 | AB20: 36.249679 | AC20: 1.8300892 | AD20: 0.043626681 | AE20: 0.018478674 | AF20: 30.924736 | AG20: 33.900695 | AH20: 30.724813 | AI20: 933675520 | AJ20: 966787072 | AK20: 134476020 | AL20: 3 | AM20: 600 | AN20: artifacts/experiments/R03/front/model.engine | AO20: results/coco-evaluation/R03-front.json | AP20: ["results/benchmarks/notebook-controlled/20260904_104755/R03/repeat-01/front_tensorrt_fp32_20260904_105940.json", "results/benchmarks/notebook-controlled/20260904_104755/R03/repeat-02/front_tensorrt_fp32_20260904_105955.json", "results/benchmarks/notebook-controlled/20260904_104755/R03/repeat-03/front_tensorrt_fp32_20260904_110010.json"] | AQ20: 437 | AR20: 86546 | AS20: b3ee83810ee62c55ccc670247a85fa94eef62ebd249388dd51736a6f84407199 | AT20: 037949731e462ecb42feb6e61b61fbca555dfe2a3d381464ad36a17b0a7ff9b9 | AU20: ["results/benchmarks/notebook-controlled/20260904_104755/R03/repeat-01/front_tensorrt_fp32_20260904_105940.json", "results/benchmarks/notebook-controlled/20260904_104755/R03/repeat-02/front_tensorrt_fp32_20260904_105955.json", "results/benchmarks/notebook-controlled/20260904_104755/R03/repeat-03/front_tensorrt_fp32_20260904_110010.json"] | AV20: FALSE | AW20: 0 | AX20: FALSE | AY20: [{"round": 1, "benchmarks": ["results/benchmarks/notebook-controlled/20260904_104755/R03/repeat-01/front_tensorrt_fp32_20260904_105940.json", "results/benchmarks/notebook-controlled/20260904_104755/R03/repeat-02/front_tensorrt_fp32_20260904_105955.json", "results/benchmarks/notebook-controlled/20260904_104755/R03/repeat-03/front_tensorrt_fp32_20260904_110010.json"], "aggregate": {"benchmark_repetitions": 3, "measured_runs_per_repetition": 200, "total_measured_runs": 600, "replicate_median_ms": [32.54655850105337, 32.933414997387445, 31.758172997797374], "replicate_mean_ms": [32.432675844938785, 33.18148440986988, 32.026792349533935], "replicate_median_mean_ms": 32.41271549874606, "replicate_median_std_ms": 0.5989439884914884, "replicate_median_cv": 0.018478673547566837, "replicate_median_ci95_low_ms": 30.92473606349131, "replicate_median_ci95_high_ms": 33.90069493400081, "mean_ms": 32.546984201447536, "median_ms": 32.38640950439731, "standard_deviation_ms": 1.4199168838885137, "coefficient_of_variation": 0.04362668058889962, "min_ms": 29.98398400086444, "max_ms": 41.25526300049387, "p05_ms": 30.67092479650455, "p25_ms": 31.504781503826962, "p75_ms": 33.33487075360608, "p95_ms": 34.875148851642734, "p99_ms": 36.249679074171574, "iqr_ms": 1.830089249779121, "fps": 30.724812898502734, "gpu_peak_allocated_bytes": 933675520, "gpu_peak_reserved_bytes": 966787072}, "official": true}]
A21: Q01 | B21: precision | C21: modelopt-int8-smoothquant | D21: int8 | E21: 1x3x504x504 | F21: 통과 | H21: 완료 | J21: 0.59315186 | K21: 0.81924579 | L21: 0.6744183 | M21: 0.043911346 | N21: 0.46790297 | O21: 0.75844833 | P21: 0.77088245 | Q21: 0.47432176 | R21: 0.68556335 | S21: 0.54520477 | T21: 0.002619724 | U21: 0.39739122 | V21: 0.53836242 | W21: 0.57725625 | X21: 0.65909655 | Y21: 25.416921 | Z21: 25.113972 | AA21: 27.84946 | AB21: 28.663698 | AC21: 1.3167165 | AD21: 0.046737362 | AE21: 0.010949709 | AF21: 24.424612 | AG21: 25.790606 | AH21: 39.343869 | AI21: 941561856 | AJ21: 1000341504 | AK21: 50137380 | AL21: 3 | AM21: 600 | AN21: artifacts/experiments/Q01/front/model.engine | AO21: results/coco-evaluation/Q01-front.json | AP21: ["results/benchmarks/notebook-controlled/20260904_104755/Q01/repeat-01/front_tensorrt_int8_20260904_110024.json", "results/benchmarks/notebook-controlled/20260904_104755/Q01/repeat-02/front_tensorrt_int8_20260904_110038.json", "results/benchmarks/notebook-controlled/20260904_104755/Q01/repeat-03/front_tensorrt_int8_20260904_110052.json"] | AQ21: 437 | AR21: 85921 | AS21: 482305be94d757175ea25f97c6f9c6823e4f524165d774c9e4fba8ca0a1157c2 | AT21: 037949731e462ecb42feb6e61b61fbca555dfe2a3d381464ad36a17b0a7ff9b9 | AU21: ["results/benchmarks/notebook-controlled/20260904_104755/Q01/repeat-01/front_tensorrt_int8_20260904_110024.json", "results/benchmarks/notebook-controlled/20260904_104755/Q01/repeat-02/front_tensorrt_int8_20260904_110038.json", "results/benchmarks/notebook-controlled/20260904_104755/Q01/repeat-03/front_tensorrt_int8_20260904_110052.json"] | AV21: FALSE | AW21: 0 | AX21: FALSE | AY21: [{"round": 1, "benchmarks": ["results/benchmarks/notebook-controlled/20260904_104755/Q01/repeat-01/front_tensorrt_int8_20260904_110024.json", "results/benchmarks/notebook-controlled/20260904_104755/Q01/repeat-02/front_tensorrt_int8_20260904_110038.json", "results/benchmarks/notebook-controlled/20260904_104755/Q01/repeat-03/front_tensorrt_int8_20260904_110052.json"], "aggregate": {"benchmark_repetitions": 3, "measured_runs_per_repetition": 200, "total_measured_runs": 600, "replicate_median_ms": [24.830207501508994, 25.11263899941696, 25.379980495927157], "replicate_mean_ms": [25.099404970314936, 25.526012699883722, 25.625345494736393], "replicate_median_mean_ms": 25.107608998951036, "replicate_median_std_ms": 0.27492101052192014, "replicate_median_cv": 0.010949708932196848, "replicate_median_ci95_low_ms": 24.424612228240672, "replicate_median_ci95_high_ms": 25.7906057696614, "mean_ms": 25.41692105497835, "median_ms": 25.113971998507623, "standard_deviation_ms": 1.187919829619974, "coefficient_of_variation": 0.046737361580910255, "min_ms": 23.49220400355989, "max_ms": 30.38223899784498, "p05_ms": 24.0032038440404, "p25_ms": 24.593713496869896, "p75_ms": 25.910429996656603, "p95_ms": 27.84945969469845, "p99_ms": 28.663697791853334, "iqr_ms": 1.3167164997867076, "fps": 39.343868513300215, "gpu_peak_allocated_bytes": 941561856, "gpu_peak_reserved_bytes": 1000341504}, "official": true}]
A22: Q02 | B22: precision | C22: modelopt-mixed-precision | D22: mixed | E22: 1x3x504x504 | F22: 통과 | H22: 완료 | J22: 0.59647515 | K22: 0.82578356 | L22: 0.66929361 | M22: 0.060998179 | N22: 0.43668754 | O22: 0.75366173 | P22: 0.77011495 | Q22: 0.48322281 | R22: 0.68976757 | S22: 0.57445001 | T22: 0.0021370481 | U22: 0.29434147 | V22: 0.54701803 | W22: 0.58141901 | X22: 0.65042712 | Y22: 25.43867 | Z22: 25.183494 | AA22: 27.596797 | AB22: 28.432948 | AC22: 1.560992 | AD22: 0.046080065 | AE22: 0.013184416 | AF22: 24.479508 | AG22: 26.137444 | AH22: 39.310232 | AI22: 941561856 | AJ22: 1000341504 | AK22: 45497556 | AL22: 3 | AM22: 600 | AN22: artifacts/experiments/Q02/front/model.engine | AO22: results/coco-evaluation/Q02-front.json | AP22: ["results/benchmarks/notebook-controlled/20260904_104755/Q02/repeat-01/front_tensorrt_mixed_20260904_110106.json", "results/benchmarks/notebook-controlled/20260904_104755/Q02/repeat-02/front_tensorrt_mixed_20260904_110119.json", "results/benchmarks/notebook-controlled/20260904_104755/Q02/repeat-03/front_tensorrt_mixed_20260904_110133.json"] | AQ22: 437 | AR22: 85786 | AS22: 3472001a47de73e1c88df401315f290d33010c10f0c218d10d96b0a29be8cf36 | AT22: 037949731e462ecb42feb6e61b61fbca555dfe2a3d381464ad36a17b0a7ff9b9 | AU22: ["results/benchmarks/notebook-controlled/20260904_104755/Q02/repeat-01/front_tensorrt_mixed_20260904_110106.json", "results/benchmarks/notebook-controlled/20260904_104755/Q02/repeat-02/front_tensorrt_mixed_20260904_110119.json", "results/benchmarks/notebook-controlled/20260904_104755/Q02/repeat-03/front_tensorrt_mixed_20260904_110133.json"] | AV22: FALSE | AW22: 0 | AX22: FALSE | AY22: [{"round": 1, "benchmarks": ["results/benchmarks/notebook-controlled/20260904_104755/Q02/repeat-01/front_tensorrt_mixed_20260904_110106.json", "results/benchmarks/notebook-controlled/20260904_104755/Q02/repeat-02/front_tensorrt_mixed_20260904_110119.json", "results/benchmarks/notebook-controlled/20260904_104755/Q02/repeat-03/front_tensorrt_mixed_20260904_110133.json"], "aggregate": {"benchmark_repetitions": 3, "measured_runs_per_repetition": 200, "total_measured_runs": 600, "replicate_median_ms": [25.52665500479634, 25.474412501353072, 24.924360997829353], "replicate_mean_ms": [25.602628129781806, 25.639870654631522, 25.073510589791113], "replicate_median_mean_ms": 25.30847616799292, "replicate_median_std_ms": 0.33367749063106594, "replicate_median_cv": 0.013184416494149125, "replicate_median_ci95_low_ms": 24.479508428760838, "replicate_median_ci95_high_ms": 26.137443907225006, "mean_ms": 25.43866979140148, "median_ms": 25.183493500662735, "standard_deviation_ms": 1.172215567058986, "coefficient_of_variation": 0.04608006537571419, "min_ms": 23.036795006191824, "max_ms": 28.759205000824295, "p05_ms": 23.833819650826626, "p25_ms": 24.58325874977163, "p75_ms": 26.144250747165643, "p95_ms": 27.59679680384579, "p99_ms": 28.432948164772824, "iqr_ms": 1.5609919973940123, "fps": 39.31023155691929, "gpu_peak_allocated_bytes": 941561856, "gpu_peak_reserved_bytes": 1000341504}, "official": true}]
A23: Q03 | B23: precision | C23: modelopt-int4-weight-only | D23: int4 | E23: 1x3x504x504 | F23: 통과 | H23: 엔진 생성 실패 | I23: returncode=1; log=results/stage2-notebook-logs/Q03-build.log | AV23: FALSE | AW23: 0 | AX23: FALSE
A24: Q04 | B24: precision | C24: modelopt-fp8 | D24: fp8 | E24: 1x3x504x504 | F24: 통과 | H24: 완료 | J24: 0.0035799376 | K24: 0.024639256 | L24: 2.9561206e-05 | M24: 0 | N24: 0.00036365651 | O24: 0.004591155 | P24: 0.15304825 | Q24: 0.37022621 | R24: 0.64124949 | S24: 0.36952719 | T24: 0.060265967 | U24: 0.24187014 | V24: 0.48801331 | W24: 0.7120392 | X24: 0.45309709 | Y24: 38.318301 | Z24: 37.993878 | AA24: 40.587289 | AB24: 41.894203 | AC24: 1.3509055 | AD24: 0.030075883 | AE24: 0.0057853307 | AF24: 37.494978 | AG24: 38.588505 | AH24: 26.097191 | AI24: 941561856 | AJ24: 1000341504 | AK24: 50411748 | AL24: 3 | AM24: 600 | AN24: artifacts/experiments/Q04/front/model.engine | AO24: results/coco-evaluation/Q04-front.json | AP24: ["results/benchmarks/notebook-controlled/20260904_104755/Q04/repeat-01/front_tensorrt_fp8_20260904_110150.json", "results/benchmarks/notebook-controlled/20260904_104755/Q04/repeat-02/front_tensorrt_fp8_20260904_110206.json", "results/benchmarks/notebook-controlled/20260904_104755/Q04/repeat-03/front_tensorrt_fp8_20260904_110223.json"] | AQ24: 437 | AR24: 87143 | AS24: 9528ac5c63f4b5e59c78bb4222c8ce50e1cbd92cfcd7ad904327cf4a0335d2d2 | AT24: 037949731e462ecb42feb6e61b61fbca555dfe2a3d381464ad36a17b0a7ff9b9 | AU24: ["results/benchmarks/notebook-controlled/20260904_104755/Q04/repeat-01/front_tensorrt_fp8_20260904_110150.json", "results/benchmarks/notebook-controlled/20260904_104755/Q04/repeat-02/front_tensorrt_fp8_20260904_110206.json", "results/benchmarks/notebook-controlled/20260904_104755/Q04/repeat-03/front_tensorrt_fp8_20260904_110223.json"] | AV24: FALSE | AW24: 0 | AX24: FALSE | AY24: [{"round": 1, "benchmarks": ["results/benchmarks/notebook-controlled/20260904_104755/Q04/repeat-01/front_tensorrt_fp8_20260904_110150.json", "results/benchmarks/notebook-controlled/20260904_104755/Q04/repeat-02/front_tensorrt_fp8_20260904_110206.json", "results/benchmarks/notebook-controlled/20260904_104755/Q04/repeat-03/front_tensorrt_fp8_20260904_110223.json"], "aggregate": {"benchmark_repetitions": 3, "measured_runs_per_repetition": 200, "total_measured_runs": 600, "replicate_median_ms": [38.1283330025326, 37.791531500261044, 38.20535950217163], "replicate_mean_ms": [38.4646704552506, 38.024205605215684, 38.46602554025594], "replicate_median_mean_ms": 38.04174133498842, "replicate_median_std_ms": 0.22008405543652626, "replicate_median_cv": 0.005785330737058208, "replicate_median_ci95_low_ms": 37.49497810702479, "replicate_median_ci95_high_ms": 38.58850456295205, "mean_ms": 38.318300533574075, "median_ms": 37.99387800245313, "standard_deviation_ms": 1.1524567305256874, "coefficient_of_variation": 0.030075883180568447, "min_ms": 36.30811999755679, "max_ms": 43.13816400099313, "p05_ms": 36.91635280192713, "p25_ms": 37.51540074517834, "p75_ms": 38.86630625129328, "p95_ms": 40.58728890195198, "p99_ms": 41.89420311253343, "iqr_ms": 1.350905506114941, "fps": 26.09719079591776, "gpu_peak_allocated_bytes": 941561856, "gpu_peak_reserved_bytes": 1000341504}, "official": true}]
